Workbook

Sheet Cover Page
B2: Investment Portfolio Dashboard
B4: Date | C4: November 18, 2025
B5: Prepared By | C5: Braeden Tuazon
B6: Purpose | C6: This tracker monitors a live investment portfolio based on real transaction data from Wealthsimple. It provides a detailed view of holdings, sector exposure, performance (realized & unrealized), and asset allocation. Designed for ongoing analysis and portfolio insights.
B8: Data Sources | C8: Wealthsimple
B10: Key Features | C10: Description
B11: Live Updates | C11: Automatically reflects current portfolio value using real-time market prices
B12: Performance Tracking | C12: Calculates both realized and unrealized gains/losses
B13: Auto-Updated Charts | C13: Sector and cap size allocations adjust with new transactions
B14: Dividend Logging | C14: Tracks dividend income from Wealthsimple payouts
B15: Fully Formula-Based | C15: No manual edits needed after entering new trades
B16: Simple Audit Trail | C16: Full history of buys, sells, and dividend activity for reference
B18: Workbook Tabs Overview | C18: Description
... B22: Chart Data Source | C22: Allocation breakdowns by sector and cap size used for visuals
B24: Disclaimer: For academic use only. Not intended as financial or investment advice.

Sheet Dashboard
B2: Investment Portfolio Dashboard
B5: Individual Holdings | O5: Lookup & Calculation Fields
B6: Name | C6: Sector | D6: Market Cap (in Billions) | E6: Cap Size | F6: # of Shares Outstanding | G6: Price per Share | H6: Total Value | I6: Allocation | J6: Beta | K6: 1 Day Return $ | L6: 1 Day Return % | M6: Total Gain / Loss | O6: Tickers | P6: Realized Gains
B7: {=_xlfn.UNIQUE(_xlfn._xlws.FILTER('Transaction Log'!$B$3:$B$246,(SUMIFS('Transaction Log'!$E$3:$E$246,'Transaction Log'!$B$3:$B$246,'Transaction Log'!$B$3:$B$246,'Transaction Log'!$C$3:$C$246,"BUY")-SUMIFS('Transaction Log'!$E$3:$E$246,'Transaction Log'!$B$3:$B$246,'Transaction Log'!$B$3:$B$246,'Transaction Log'!$C$3:$C$246,"SELL"))>0))} -> #VALUE! | C7: Global Equity ETF | D7: {=_FV(B7,"Market cap",TRUE)} -> 1.1753419e+10 | E7: =IF(ISNUMBER(D7),IF(D7>10000000000,"Large",IF(D7>2000000000,"Mid","Small")),"N/A") -> Large | F7: =SUMIFS('Transaction Log'!$E$3:$E$246,'Transaction Log'!$B$3:$B$246,B7,'Transaction Log'!$C$3:$C$246,"BUY") -SUMIFS('Transaction Log'!$E$3:$E$246,'Transaction Log'!$B$3:$B$246,B7,'Transaction Log'!$C$3:$C$246,"SELL") -> 123.8272 | G7: {=_FV(B7,"Price")} -> 39.97 | H7: =F7*G7 -> 4949.3732 | I7: =H7/SUM(H$7:H$22) -> 0.21955716 | J7: {=IFERROR(_FV(B7,"Beta"), 0)} -> 0.9474 | K7: {=IFERROR(F7*(G7 - _xlfn.FIELDVALUE(B7,"Previous close")),0)} -> -38.386432 | L7: {=IFERROR((G7 -_FV( B7,"Previous close",TRUE)) /_FV( B7,"Previous close",TRUE), 0)} -> -0.0076961271 | M7: =VLOOKUP(B7,'Realized Gains & Losses'!$B:$H,7,FALSE) + F7*(G7 - VLOOKUP(B7,'Realized Gains & Losses'!$B:$D,3,FALSE)) -> 1212.4932 | O7: {=_FV(B7,"Ticker symbol",TRUE)} -> XEQT | P7: =VLOOKUP(B7,'Realized Gains & Losses'!$B:$H,7,0) -> 376.18028
B8: #VALUE! | C8: US Equity ETF | D8: {=_FV(B8,"Market cap",TRUE)} -> 2.7770155e+10 | E8: =IF(ISNUMBER(D8),IF(D8>10000000000,"Large",IF(D8>2000000000,"Mid","Small")),"N/A") -> Large | F8: =SUMIFS('Transaction Log'!$E$3:$E$246,'Transaction Log'!$B$3:$B$246,B8,'Transaction Log'!$C$3:$C$246,"BUY") -SUMIFS('Transaction Log'!$E$3:$E$246,'Transaction Log'!$B$3:$B$246,B8,'Transaction Log'!$C$3:$C$246,"SELL") -> 52.2578 | G8: {=_FV(B8,"Price")} -> 168.78 | H8: =F8*G8 -> 8820.0715 | I8: =H8/SUM(H$7:H$22) -> 0.39126366 | J8: {=IFERROR(_FV(B8,"Beta"), 0)} -> 0.9828 | K8: {=IFERROR(F8*(G8 - _xlfn.FIELDVALUE(B8,"Previous close")),0)} -> -61.664204 | L8: {=IFERROR((G8 -_FV( B8,"Previous close",TRUE)) /_FV( B8,"Previous close",TRUE), 0)} -> -0.0069428101 | M8: =VLOOKUP(B8,'Realized Gains & Losses'!$B:$H,7,FALSE) + F8*(G8 - VLOOKUP(B8,'Realized Gains & Losses'!$B:$D,3,FALSE)) -> 1394.3415 | O8: {=_FV(B8,"Ticker symbol",TRUE)} -> VFV | P8: =VLOOKUP(B8,'Realized Gains & Losses'!$B:$H,7,0) -> 293.76103
B9: #VALUE! | C9: Technology Equity ETF | D9: {=_FV(B9,"Market cap",TRUE)} -> 3753248843 | E9: =IF(ISNUMBER(D9),IF(D9>10000000000,"Large",IF(D9>2000000000,"Mid","Small")),"N/A") -> Mid | F9: =SUMIFS('Transaction Log'!$E$3:$E$246,'Transaction Log'!$B$3:$B$246,B9,'Transaction Log'!$C$3:$C$246,"BUY") -SUMIFS('Transaction Log'!$E$3:$E$246,'Transaction Log'!$B$3:$B$246,B9,'Transaction Log'!$C$3:$C$246,"SELL") -> 20.0079 | G9: {=_FV(B9,"Price")} -> 54.21 | H9: =F9*G9 -> 1084.6283 | I9: =H9/SUM(H$7:H$22) -> 0.048114759 | J9: {=IFERROR(_FV(B9,"Beta"), 0)} -> 0.9608 | K9: {=IFERROR(F9*(G9 - _xlfn.FIELDVALUE(B9,"Previous close")),0)} -> -4.00158 | L9: {=IFERROR((G9 -_FV( B9,"Previous close",TRUE)) /_FV( B9,"Previous close",TRUE), 0)} -> -0.0036757949 | M9: =VLOOKUP(B9,'Realized Gains & Losses'!$B:$H,7,FALSE) + F9*(G9 - VLOOKUP(B9,'Realized Gains & Losses'!$B:$D,3,FALSE)) -> 178.35826 | O9: {=_FV(B9,"Ticker symbol",TRUE)} -> TEC | P9: =VLOOKUP(B9,'Realized Gains & Losses'!$B:$H,7,0) -> -12.337004
B10: #VALUE! | C10: Semiconductors & Semiconductor Equipment | D10: {=_FV(B10,"Market cap",TRUE)} -> 4456134000000 | E10: =IF(ISNUMBER(D10),IF(D10>10000000000,"Large",IF(D10>2000000000,"Mid","Small")),"N/A") -> Large | F10: =SUMIFS('Transaction Log'!$E$3:$E$246,'Transaction Log'!$B$3:$B$246,B10,'Transaction Log'!$C$3:$C$246,"BUY") -SUMIFS('Transaction Log'!$E$3:$E$246,'Transaction Log'!$B$3:$B$246,B10,'Transaction Log'!$C$3:$C$246,"SELL") -> 9.0017 | G10: {=_FV(B10,"Price")} -> 41.48 | H10: =F10*G10 -> 373.39052 | I10: =H10/SUM(H$7:H$22) -> 0.016563827 | J10: {=IFERROR(_FV(B10,"Beta"), 0)} -> 2.3148 | K10: {=IFERROR(F10*(G10 - _xlfn.FIELDVALUE(B10,"Previous close")),0)} -> -1.980374 | L10: {=IFERROR((G10 -_FV( B10,"Previous close",TRUE)) /_FV( B10,"Previous close",TRUE), 0)} -> -0.0052757794 | M10: =VLOOKUP(B10,'Realized Gains & Losses'!$B:$H,7,FALSE) + F10*(G10 - VLOOKUP(B10,'Realized Gains & Losses'!$B:$D,3,FALSE)) -> -11.129484 | O10: {=_FV(B10,"Ticker symbol",TRUE)} -> NVDA | P10: =VLOOKUP(B10,'Realized Gains & Losses'!$B:$H,7,0) -> -83.74409
B11: #VALUE! | C11: Canadian Dividend ETF | D11: {=_FV(B11,"Market cap",TRUE)} -> 5.2633955e+09 | E11: =IF(ISNUMBER(D11),IF(D11>10000000000,"Large",IF(D11>2000000000,"Mid","Small")),"N/A") -> Mid | F11: =SUMIFS('Transaction Log'!$E$3:$E$246,'Transaction Log'!$B$3:$B$246,B11,'Transaction Log'!$C$3:$C$246,"BUY") -SUMIFS('Transaction Log'!$E$3:$E$246,'Transaction Log'!$B$3:$B$246,B11,'Transaction Log'!$C$3:$C$246,"SELL") -> 7.0466 | G11: {=_FV(B11,"Price")} -> 61.14 | H11: =F11*G11 -> 430.82912 | I11: =H11/SUM(H$7:H$22) -> 0.019111838 | J11: {=IFERROR(_FV(B11,"Beta"), 0)} -> 0.979 | K11: {=IFERROR(F11*(G11 - _xlfn.FIELDVALUE(B11,"Previous close")),0)} -> -0.070466 | L11: {=IFERROR((G11 -_FV( B11,"Previous close",TRUE)) /_FV( B11,"Previous close",TRUE), 0)} -> -0.0001635323 | M11: =VLOOKUP(B11,'Realized Gains & Losses'!$B:$H,7,FALSE) + F11*(G11 - VLOOKUP(B11,'Realized Gains & Losses'!$B:$D,3,FALSE)) -> 212.28912 | O11: {=_FV(B11,"Ticker symbol",TRUE)} -> VDY | P11: =VLOOKUP(B11,'Realized Gains & Losses'!$B:$H,7,0) -> 123.54246
B12: #VALUE! | C12: Consumer Technology / Hardware | D12: {=_FV(B12,"Market cap",TRUE)} -> 4147722000000 | E12: =IF(ISNUMBER(D12),IF(D12>10000000000,"Large",IF(D12>2000000000,"Mid","Small")),"N/A") -> Large | F12: =SUMIFS('Transaction Log'!$E$3:$E$246,'Transaction Log'!$B$3:$B$246,B12,'Transaction Log'!$C$3:$C$246,"BUY") -SUMIFS('Transaction Log'!$E$3:$E$246,'Transaction Log'!$B$3:$B$246,B12,'Transaction Log'!$C$3:$C$246,"SELL") -> 15.0293 | G12: {=_FV(B12,"Price")} -> 39.91 | H12: =F12*G12 -> 599.81936 | I12: =H12/SUM(H$7:H$22) -> 0.026608346 | J12: {=IFERROR(_FV(B12,"Beta"), 0)} -> 1.0902 | K12: {=IFERROR(F12*(G12 - _xlfn.FIELDVALUE(B12,"Previous close")),0)} -> -3.757325 | L12: {=IFERROR((G12 -_FV( B12,"Previous close",TRUE)) /_FV( B12,"Previous close",TRUE), 0)} -> -0.0062250996 | M12: =VLOOKUP(B12,'Realized Gains & Losses'!$B:$H,7,FALSE) + F12*(G12 - VLOOKUP(B12,'Realized Gains & Losses'!$B:$D,3,FALSE)) -> 199.39936 | O12: {=_FV(B12,"Ticker symbol",TRUE)} -> AAPL | P12: =VLOOKUP(B12,'Realized Gains & Losses'!$B:$H,7,0) -> 77.481814
B13: #VALUE! | C13: Consumer Discretionary / E-Commerce & Retail | D13: {=_FV(B13,"Market cap",TRUE)} -> 2449236000000 | E13: =IF(ISNUMBER(D13),IF(D13>10000000000,"Large",IF(D13>2000000000,"Mid","Small")),"N/A") -> Large | F13: =SUMIFS('Transaction Log'!$E$3:$E$246,'Transaction Log'!$B$3:$B$246,B13,'Transaction Log'!$C$3:$C$246,"BUY") -SUMIFS('Transaction Log'!$E$3:$E$246,'Transaction Log'!$B$3:$B$246,B13,'Transaction Log'!$C$3:$C$246,"SELL") -> 16 | G13: {=_FV(B13,"Price")} -> 26.69 | H13: =F13*G13 -> 427.04 | I13: =H13/SUM(H$7:H$22) -> 0.01894375 | J13: {=IFERROR(_FV(B13,"Beta"), 0)} -> 1.3763 | K13: {=IFERROR(F13*(G13 - _xlfn.FIELDVALUE(B13,"Previous close")),0)} -> 0.48 | L13: {=IFERROR((G13 -_FV( B13,"Previous close",TRUE)) /_FV( B13,"Previous close",TRUE), 0)} -> 0.0011252813 | M13: =VLOOKUP(B13,'Realized Gains & Losses'!$B:$H,7,FALSE) + F13*(G13 - VLOOKUP(B13,'Realized Gains & Losses'!$B:$D,3,FALSE)) -> 31.59 | O13: {=_FV(B13,"Ticker symbol",TRUE)} -> AMZN | P13: =VLOOKUP(B13,'Realized Gains & Losses'!$B:$H,7,0) -> -6.3388889
B14: #VALUE! | C14: Banking Services | D14: {=_FV(B14,"Market cap",TRUE)} -> 314633618080 | E14: =IF(ISNUMBER(D14),IF(D14>10000000000,"Large",IF(D14>2000000000,"Mid","Small")),"N/A") -> Large | F14: =SUMIFS('Transaction Log'!$E$3:$E$246,'Transaction Log'!$B$3:$B$246,B14,'Transaction Log'!$C$3:$C$246,"BUY") -SUMIFS('Transaction Log'!$E$3:$E$246,'Transaction Log'!$B$3:$B$246,B14,'Transaction Log'!$C$3:$C$246,"SELL") -> 2.0329 | G14: {=_FV(B14,"Price")} -> 224.72 | H14: =F14*G14 -> 456.83329 | I14: =H14/SUM(H$7:H$22) -> 0.020265398 | J14: {=IFERROR(_FV(B14,"Beta"), 0)} -> 1.0034 | K14: {=IFERROR(F14*(G14 - _xlfn.FIELDVALUE(B14,"Previous close")),0)} -> 1.341714 | L14: {=IFERROR((G14 -_FV( B14,"Previous close",TRUE)) /_FV( B14,"Previous close",TRUE), 0)} -> 0.0029456396 | M14: =VLOOKUP(B14,'Realized Gains & Losses'!$B:$H,7,FALSE) + F14*(G14 - VLOOKUP(B14,'Realized Gains & Losses'!$B:$D,3,FALSE)) -> 125.23329 | O14: {=_FV(B14,"Ticker symbol",TRUE)} -> RY | P14: =VLOOKUP(B14,'Realized Gains & Losses'!$B:$H,7,0) -> 7.11389
B15: #VALUE! | C15: Oil & Gas Midstream / Pipelines | D15: {=_FV(B15,"Market cap",TRUE)} -> 145229356080 | E15: =IF(ISNUMBER(D15),IF(D15>10000000000,"Large",IF(D15>2000000000,"Mid","Small")),"N/A") -> Large | F15: =SUMIFS('Transaction Log'!$E$3:$E$246,'Transaction Log'!$B$3:$B$246,B15,'Transaction Log'!$C$3:$C$246,"BUY") -SUMIFS('Transaction Log'!$E$3:$E$246,'Transaction Log'!$B$3:$B$246,B15,'Transaction Log'!$C$3:$C$246,"SELL") -> 1 | G15: {=_FV(B15,"Price")} -> 66.58 | H15: =F15*G15 -> 66.58 | I15: =H15/SUM(H$7:H$22) -> 0.0029535287 | J15: {=IFERROR(_FV(B15,"Beta"), 0)} -> 0.8258 | K15: {=IFERROR(F15*(G15 - _xlfn.FIELDVALUE(B15,"Previous close")),0)} -> -0.68 | L15: {=IFERROR((G15 -_FV( B15,"Previous close",TRUE)) /_FV( B15,"Previous close",TRUE), 0)} -> -0.010110021 | M15: =VLOOKUP(B15,'Realized Gains & Losses'!$B:$H,7,FALSE) + F15*(G15 - VLOOKUP(B15,'Realized Gains & Losses'!$B:$D,3,FALSE)) -> 26.99 | O15: {=_FV(B15,"Ticker symbol",TRUE)} -> ENB | P15: =VLOOKUP(B15,'Realized Gains & Losses'!$B:$H,7,0) -> 20.53
B16: #VALUE! | C16: Utilities & Power Generation | D16: {=_FV(B16,"Market cap",TRUE)} -> 9720957325 | E16: =IF(ISNUMBER(D16),IF(D16>10000000000,"Large",IF(D16>2000000000,"Mid","Small")),"N/A") -> Mid | F16: =SUMIFS('Transaction Log'!$E$3:$E$246,'Transaction Log'!$B$3:$B$246,B16,'Transaction Log'!$C$3:$C$246,"BUY") -SUMIFS('Transaction Log'!$E$3:$E$246,'Transaction Log'!$B$3:$B$246,B16,'Transaction Log'!$C$3:$C$246,"SELL") -> 2 | G16: {=_FV(B16,"Price")} -> 62.35 | H16: =F16*G16 -> 124.7 | I16: =H16/SUM(H$7:H$22) -> 0.0055317667 | J16: {=IFERROR(_FV(B16,"Beta"), 0)} -> 0.3876 | K16: {=IFERROR(F16*(G16 - _xlfn.FIELDVALUE(B16,"Previous close")),0)} -> -0.06 | L16: {=IFERROR((G16 -_FV( B16,"Previous close",TRUE)) /_FV( B16,"Previous close",TRUE), 0)} -> -0.00048092337 | M16: =VLOOKUP(B16,'Realized Gains & Losses'!$B:$H,7,FALSE) + F16*(G16 - VLOOKUP(B16,'Realized Gains & Losses'!$B:$D,3,FALSE)) -> -44.83 | O16: {=_FV(B16,"Ticker symbol",TRUE)} -> CPX | P16: =VLOOKUP(B16,'Realized Gains & Losses'!$B:$H,7,0) -> -49.923846
B17: #VALUE! | C17: Global Growth / Innovation ETF | D17: {=_FV(B17,"Market cap",TRUE)} -> 1.4665676e+09 | E17: =IF(ISNUMBER(D17),IF(D17>10000000000,"Large",IF(D17>2000000000,"Mid","Small")),"N/A") -> Small | F17: =SUMIFS('Transaction Log'!$E$3:$E$246,'Transaction Log'!$B$3:$B$246,B17,'Transaction Log'!$C$3:$C$246,"BUY") -SUMIFS('Transaction Log'!$E$3:$E$246,'Transaction Log'!$B$3:$B$246,B17,'Transaction Log'!$C$3:$C$246,"SELL") -> 56 | G17: {=_FV(B17,"Price")} -> 23.36 | H17: =F17*G17 -> 1308.16 | I17: =H17/SUM(H$7:H$22) -> 0.058030761 | J17: {=IFERROR(_FV(B17,"Beta"), 0)} -> 0 | K17: {=IFERROR(F17*(G17 - _xlfn.FIELDVALUE(B17,"Previous close")),0)} -> -6.16 | L17: {=IFERROR((G17 -_FV( B17,"Previous close",TRUE)) /_FV( B17,"Previous close",TRUE), 0)} -> -0.0046868343 | M17: =VLOOKUP(B17,'Realized Gains & Losses'!$B:$H,7,FALSE) + F17*(G17 - VLOOKUP(B17,'Realized Gains & Losses'!$B:$D,3,FALSE)) -> 183.48 | O17: {=_FV(B17,"Ticker symbol",TRUE)} -> FINN | P17: =VLOOKUP(B17,'Realized Gains & Losses'!$B:$H,7,0) -> -36.22
B18: #VALUE! | C18: Nuclear Energy / Energy Technology | D18: {=_FV(B18,"Market cap",TRUE)} -> 16349696544 | E18: =IF(ISNUMBER(D18),IF(D18>10000000000,"Large",IF(D18>2000000000,"Mid","Small")),"N/A") -> Large | F18: =SUMIFS('Transaction Log'!$E$3:$E$246,'Transaction Log'!$B$3:$B$246,B18,'Transaction Log'!$C$3:$C$246,"BUY") -SUMIFS('Transaction Log'!$E$3:$E$246,'Transaction Log'!$B$3:$B$246,B18,'Transaction Log'!$C$3:$C$246,"SELL") -> 1 | G18: {=_FV(B18,"Price")} -> 104.64 | H18: =F18*G18 -> 104.64 | I18: =H18/SUM(H$7:H$22) -> 0.0046418931 | J18: {=IFERROR(_FV(B18,"Beta"), 0)} -> 0.7354 | K18: {=IFERROR(F18*(G18 - _xlfn.FIELDVALUE(B18,"Previous close")),0)} -> -7.01 | L18: {=IFERROR((G18 -_FV( B18,"Previous close",TRUE)) /_FV( B18,"Previous close",TRUE), 0)} -> -0.06278549 | M18: =VLOOKUP(B18,'Realized Gains & Losses'!$B:$H,7,FALSE) + F18*(G18 - VLOOKUP(B18,'Realized Gains & Losses'!$B:$D,3,FALSE)) -> 25.43 | O18: {=_FV(B18,"Ticker symbol",TRUE)} -> OKLO | P18: =VLOOKUP(B18,'Realized Gains & Losses'!$B:$H,7,0) -> 0
B19: #VALUE! | C19: Money Market ETF | D19: {=IFERROR(_xlfn.FIELDVALUE(B19, "Market cap"), "N/A")} -> N/A | E19: =IF(ISNUMBER(D19),IF(D19>10000000000,"Large",IF(D19>2000000000,"Mid","Small")),"N/A") -> N/A | F19: =SUMIFS('Transaction Log'!$E$3:$E$246,'Transaction Log'!$B$3:$B$246,B19,'Transaction Log'!$C$3:$C$246,"BUY") -SUMIFS('Transaction Log'!$E$3:$E$246,'Transaction Log'!$B$3:$B$246,B19,'Transaction Log'!$C$3:$C$246,"SELL") -> 66.6223 | G19: {=_FV(B19,"Price")} -> 49.85 | H19: =F19*G19 -> 3321.1217 | I19: =H19/SUM(H$7:H$22) -> 0.14732695 | J19: {=IFERROR(_FV(B19,"Beta"), 0)} -> 0 | K19: {=IFERROR(F19*(G19 - _xlfn.FIELDVALUE(B19,"Previous close")),0)} -> 0 | L19: {=IFERROR((G19 -_FV( B19,"Previous close",TRUE)) /_FV( B19,"Previous close",TRUE), 0)} -> 0 | M19: =VLOOKUP(B19,'Realized Gains & Losses'!$B:$H,7,FALSE) + F19*(G19 - VLOOKUP(B19,'Realized Gains & Losses'!$B:$D,3,FALSE)) -> 91.981655 | O19: {=_FV(B19,"Ticker symbol",TRUE)} -> ZMMK | P19: =VLOOKUP(B19,'Realized Gains & Losses'!$B:$H,7,0) -> 97.031822
B20: #VALUE! | C20: Passenger Transportation / Airlines | D20: {=_FV(B20,"Market cap",TRUE)} -> 5627854000 | E20: =IF(ISNUMBER(D20),IF(D20>10000000000,"Large",IF(D20>2000000000,"Mid","Small")),"N/A") -> Mid | F20: =SUMIFS('Transaction Log'!$E$3:$E$246,'Transaction Log'!$B$3:$B$246,B20,'Transaction Log'!$C$3:$C$246,"BUY") -SUMIFS('Transaction Log'!$E$3:$E$246,'Transaction Log'!$B$3:$B$246,B20,'Transaction Log'!$C$3:$C$246,"SELL") -> 10 | G20: {=_FV(B20,"Price")} -> 18.87 | H20: =F20*G20 -> 188.7 | I20: =H20/SUM(H$7:H$22) -> 0.0083708451 | J20: {=IFERROR(_FV(B20,"Beta"), 0)} -> 1.7182 | K20: {=IFERROR(F20*(G20 - _xlfn.FIELDVALUE(B20,"Previous close")),0)} -> -1.2 | L20: {=IFERROR((G20 -_FV( B20,"Previous close",TRUE)) /_FV( B20,"Previous close",TRUE), 0)} -> -0.0063191153 | M20: =VLOOKUP(B20,'Realized Gains & Losses'!$B:$H,7,FALSE) + F20*(G20 - VLOOKUP(B20,'Realized Gains & Losses'!$B:$D,3,FALSE)) -> -5 | O20: {=_FV(B20,"Ticker symbol",TRUE)} -> AC | P20: =VLOOKUP(B20,'Realized Gains & Losses'!$B:$H,7,0) -> 0
B21: #VALUE! | C21: Freight & Logistics Services | D21: {=_FV(B21,"Market cap",TRUE)} -> 80494825728 | E21: =IF(ISNUMBER(D21),IF(D21>10000000000,"Large",IF(D21>2000000000,"Mid","Small")),"N/A") -> Large | F21: =SUMIFS('Transaction Log'!$E$3:$E$246,'Transaction Log'!$B$3:$B$246,B21,'Transaction Log'!$C$3:$C$246,"BUY") -SUMIFS('Transaction Log'!$E$3:$E$246,'Transaction Log'!$B$3:$B$246,B21,'Transaction Log'!$C$3:$C$246,"SELL") -> 1 | G21: {=_FV(B21,"Price")} -> 94.88 | H21: =F21*G21 -> 94.88 | I21: =H21/SUM(H$7:H$22) -> 0.0042089337 | J21: {=IFERROR(_FV(B21,"Beta"), 0)} -> 1.102 | K21: {=IFERROR(F21*(G21 - _xlfn.FIELDVALUE(B21,"Previous close")),0)} -> 0.12 | L21: {=IFERROR((G21 -_FV( B21,"Previous close",TRUE)) /_FV( B21,"Previous close",TRUE), 0)} -> 0.0012663571 | M21: =VLOOKUP(B21,'Realized Gains & Losses'!$B:$H,7,FALSE) + F21*(G21 - VLOOKUP(B21,'Realized Gains & Losses'!$B:$D,3,FALSE)) -> -27.35 | O21: {=_FV(B21,"Ticker symbol",TRUE)} -> UPS | P21: =VLOOKUP(B21,'Realized Gains & Losses'!$B:$H,7,0) -> 0
B22: #VALUE! | C22: Canadian Equity ETF | D22: {=_FV(B22,"Market cap",TRUE)} -> 1.2348752e+10 | E22: =IF(ISNUMBER(D22),IF(D22>10000000000,"Large",IF(D22>2000000000,"Mid","Small")),"N/A") -> Large | F22: =SUMIFS('Transaction Log'!$E$3:$E$246,'Transaction Log'!$B$3:$B$246,B22,'Transaction Log'!$C$3:$C$246,"BUY") -SUMIFS('Transaction Log'!$E$3:$E$246,'Transaction Log'!$B$3:$B$246,B22,'Transaction Log'!$C$3:$C$246,"SELL") -> 3 | G22: {=_FV(B22,"Price")} -> 63.92 | H22: =F22*G22 -> 191.76 | I22: =H22/SUM(H$7:H$22) -> 0.0085065885 | J22: {=IFERROR(_FV(B22,"Beta"), 0)} -> 0.9992 | K22: {=IFERROR(F22*(G22 - _xlfn.FIELDVALUE(B22,"Previous close")),0)} -> -1.11 | L22: {=IFERROR((G22 -_FV( B22,"Previous close",TRUE)) /_FV( B22,"Previous close",TRUE), 0)} -> -0.0057551719 | M22: =VLOOKUP(B22,'Realized Gains & Losses'!$B:$H,7,FALSE) + F22*(G22 - VLOOKUP(B22,'Realized Gains & Losses'!$B:$D,3,FALSE)) -> 7.27 | O22: {=_FV(B22,"Ticker symbol",TRUE)} -> VCN | P22: =VLOOKUP(B22,'Realized Gains & Losses'!$B:$H,7,0) -> 0
B23: Portfolio Performance Summary
L25: Portfolio Summary
L26: Total Gain/Loss $ | M26: =SUM(M7:M22)+(SUM('Realized Gains & Losses'!H4:H29)-SUM(Dashboard!P7:P22)) -> 3629.1069
L27: Daily Gain/Loss $ | M27: =SUM(K7:K22) -> -124.13867
L28: Daily Gain/Loss % | M28: =SUMPRODUCT(I7:I22,L7:L22) -> -0.0054506774

Sheet Transaction Log
B2: Stock Ticker | C2: Transaction | D2: Date | E2: Quantity | F2: Price | G2: Dividend | H2: Total Amount
B3: #VALUE! | C3: BUY | D3: 45477 | E3: 1 | F3: 30.83 | H3: ='Transaction Log'!$F3*'Transaction Log'!$E3 -> 30.83
B4: #VALUE! | C4: BUY | D4: 45477 | E4: 0.2507 | F4: 133.22696 | H4: ='Transaction Log'!$F4*'Transaction Log'!$E4 -> 33.4
B5: #VALUE! | C5: BUY | D5: 45477 | E5: 1.1566 | F5: 30.926855 | H5: ='Transaction Log'!$F5*'Transaction Log'!$E5 -> 35.77
B6: #VALUE! | C6: BUY | D6: 45478 | E6: 25.7815 | F6: 31.030002 | H6: ='Transaction Log'!$F6*'Transaction Log'!$E6 -> 800
B7: #VALUE! | C7: BUY | D7: 45478 | E7: 0.6109 | F7: 40.923228 | H7: ='Transaction Log'!$F7*'Transaction Log'!$E7 -> 25
B8: #VALUE! | C8: BUY | D8: 45481 | E8: 1 | F8: 120.27 | H8: ='Transaction Log'!$F8*'Transaction Log'!$E8 -> 120.27
B9: #VALUE! | C9: BUY | D9: 45481 | E9: 2 | F9: 25.08 | H9: ='Transaction Log'!$F9*'Transaction Log'!$E9 -> 50.16
B10: #VALUE! | C10: BUY | D10: 45481 | E10: 2 | F10: 133.8 | H10: ='Transaction Log'!$F10*'Transaction Log'!$E10 -> 267.6
B11: #VALUE! | C11: BUY | D11: 45481 | E11: 1.4686 | F11: 41.182078 | H11: ='Transaction Log'!$F11*'Transaction Log'!$E11 -> 60.48
B12: #VALUE! | C12: BUY | D12: 45481 | E12: 16.1186 | F12: 31.020064 | H12: ='Transaction Log'!$F12*'Transaction Log'!$E12 -> 500
B13: #VALUE! | C13: BUY | D13: 45481 | E13: 0.4924 | F13: 43.643379 | H13: ='Transaction Log'!$F13*'Transaction Log'!$E13 -> 21.49
B14: #VALUE! | C14: BUY | D14: 45482 | E14: 2 | F14: 50.06 | H14: ='Transaction Log'!$F14*'Transaction Log'!$E14 -> 100.12
... B30: #VALUE! | C30: BUY | D30: 45491 | E30: 1.3557 | F30: 136.01092 | H30: ='Transaction Log'!$F30*'Transaction Log'!$E30 -> 184.39
B31: #VALUE! | C31: DIV | D31: 45504 | G31: 0.23 | H31: ='Transaction Log'!$F31*'Transaction Log'!$E31 -> 0
B32: #VALUE! | C32: BUY | D32: 45506 | E32: 4 | F32: 135.75 | H32: ='Transaction Log'!$F32*'Transaction Log'!$E32 -> 543
B33: #VALUE! | C33: BUY | D33: 45510 | E33: 9.1393 | F33: 50.03009 | H33: ='Transaction Log'!$F33*'Transaction Log'!$E33 -> 457.24
B34: #VALUE! | C34: DIV | D34: 45512 | G34: 1.56 | H34: ='Transaction Log'!$F34*'Transaction Log'!$E34 -> 0
B35: #VALUE! | C35: DIV | D35: 45512 | G35: 0.74 | H35: ='Transaction Log'!$F35*'Transaction Log'!$E35 -> 0
B36: #VALUE! | C36: DIV | D36: 45526 | G36: 0.07 | H36: ='Transaction Log'!$F36*'Transaction Log'!$E36 -> 0
B37: #VALUE! | C37: SELL | D37: 45527 | E37: 1 | F37: 26.87 | H37: ='Transaction Log'!$F37*'Transaction Log'!$E37 -> 26.87
B38: #VALUE! | C38: SELL | D38: 45527 | E38: 2 | F38: 21.15 | H38: ='Transaction Log'!$F38*'Transaction Log'!$E38 -> 42.3
B39: #VALUE! | C39: BUY | D39: 45531 | E39: 0.5046 | F39: 46.690448 | H39: ='Transaction Log'!$F39*'Transaction Log'!$E39 -> 23.56
B40: #VALUE! | C40: DIV | D40: 45531 | G40: 3.1 | H40: ='Transaction Log'!$F40*'Transaction Log'!$E40 -> 0
B41: #VALUE! | C41: BUY | D41: 45533 | E41: 15 | F41: 30.18 | H41: ='Transaction Log'!$F41*'Transaction Log'!$E41 -> 452.7
B42: #VALUE! | C42: SELL | D42: 45533 | E42: 2 | F42: 26.16 | H42: ='Transaction Log'!$F42*'Transaction Log'!$E42 -> 52.32
B43: #VALUE! | C43: BUY | D43: 45534 | E43: 1 | F43: 33.89 | H43: ='Transaction Log'!$F43*'Transaction Log'!$E43 -> 33.89
B44: #VALUE! | C44: BUY | D44: 45534 | E44: 5 | F44: 46.6 | H44: ='Transaction Log'!$F44*'Transaction Log'!$E44 -> 233
B45: #VALUE! | C45: BUY | D45: 45534 | E45: 4 | F45: 46.6 | H45: ='Transaction Log'!$F45*'Transaction Log'!$E45 -> 186.4
B46: #VALUE! | C46: DIV | D46: 45534 | G46: 0.23 | H46: ='Transaction Log'!$F46*'Transaction Log'!$E46 -> 0
B47: #VALUE! | C47: BUY | D47: 45538 | E47: 10.8943 | F47: 50.015146 | H47: ='Transaction Log'!$F47*'Transaction Log'!$E47 -> 544.88
B48: #VALUE! | C48: DIV | D48: 45544 | G48: 3.09 | H48: ='Transaction Log'!$F48*'Transaction Log'!$E48 -> 0
B49: #VALUE! | C49: DIV | D49: 45546 | G49: 2.72 | H49: ='Transaction Log'!$F49*'Transaction Log'!$E49 -> 0
B50: #VALUE! | C50: BUY | D50: 45551 | E50: 13 | F50: 47.56 | H50: ='Transaction Log'!$F50*'Transaction Log'!$E50 -> 618.28
B51: #VALUE! | C51: SELL | D51: 45552 | E51: 2 | F51: 117.65 | H51: ='Transaction Log'!$F51*'Transaction Log'!$E51 -> 235.3
B52: #VALUE! | C52: BUY | D52: 45552 | E52: 1 | F52: 167.38 | H52: ='Transaction Log'!$F52*'Transaction Log'!$E52 -> 167.38
B53: #VALUE! | C53: BUY | D53: 45553 | E53: 2 | F53: 47.83 | H53: ='Transaction Log'!$F53*'Transaction Log'!$E53 -> 95.66
B54: #VALUE! | C54: SELL | D54: 45558 | E54: 3 | F54: 34.02 | H54: ='Transaction Log'!$F54*'Transaction Log'!$E54 -> 102.06
B55: #VALUE! | C55: SELL | D55: 45558 | E55: 28 | F55: 50.12 | H55: ='Transaction Log'!$F55*'Transaction Log'!$E55 -> 1403.36
B56: #VALUE! | C56: BUY | D56: 45558 | E56: 10 | F56: 48.08 | H56: ='Transaction Log'!$F56*'Transaction Log'!$E56 -> 480.8
...

Sheet Realized Gains & Losses
C2: Purchases | E2: Sales | G2: Dividends Received | H2: Realized Gain/(Loss) $
B3: Stock | C3: # of Shares | D3: Price per Share | E3: # of Shares | F3: Price per Share
B4: {=_xlfn.UNIQUE('Transaction Log'!$B$3:$B$246)} -> #VALUE! | C4: =SUMIFS('Transaction Log'!$E$3:$E$246,'Transaction Log'!$B$3:$B$246,'Realized Gains & Losses'!B4,'Transaction Log'!$C$3:$C$246,"BUY") -> 291.8272 | D4: {=IFERROR(SUMPRODUCT(('Transaction Log'!$B$3:$B$246=B4)*('Transaction Log'!$C$3:$C$246="BUY")*'Transaction Log'!$H$3:$H$246)/C4,"")} -> 33.216129 | E4: =SUMIFS('Transaction Log'!$E$3:$E$246,'Transaction Log'!$B$3:$B$246,'Realized Gains & Losses'!B4,'Transaction Log'!$C$3:$C$246,"SELL") -> 168 | F4: {=IFERROR(SUMPRODUCT(('Transaction Log'!$B$3:$B$246=B4)*('Transaction Log'!$C$3:$C$246="SELL")*'Transaction Log'!$H$3:$H$246)/E4,)} -> 34.811905 | G4: =SUMIFS('Transaction Log'!$G$3:$G$246,'Transaction Log'!$B$3:$B$246,B4,'Transaction Log'!$C$3:$C$246,"DIV") -> 108.09 | H4: =(E4*(F4-D4))+G4 -> 376.18028
B5: #VALUE! | C5: =SUMIFS('Transaction Log'!$E$3:$E$246,'Transaction Log'!$B$3:$B$246,'Realized Gains & Losses'!B5,'Transaction Log'!$C$3:$C$246,"BUY") -> 104.2578 | D5: {=IFERROR(SUMPRODUCT(('Transaction Log'!$B$3:$B$246=B5)*('Transaction Log'!$C$3:$C$246="BUY")*'Transaction Log'!$H$3:$H$246)/C5,"")} -> 147.7194 | E5: =SUMIFS('Transaction Log'!$E$3:$E$246,'Transaction Log'!$B$3:$B$246,'Realized Gains & Losses'!B5,'Transaction Log'!$C$3:$C$246,"SELL") -> 52 | F5: {=IFERROR(SUMPRODUCT(('Transaction Log'!$B$3:$B$246=B5)*('Transaction Log'!$C$3:$C$246="SELL")*'Transaction Log'!$H$3:$H$246)/E5,)} -> 152.04 | G5: =SUMIFS('Transaction Log'!$G$3:$G$246,'Transaction Log'!$B$3:$B$246,B5,'Transaction Log'!$C$3:$C$246,"DIV") -> 69.09 | H5: =(E5*(F5-D5))+G5 -> 293.76103
B6: #VALUE! | C6: =SUMIFS('Transaction Log'!$E$3:$E$246,'Transaction Log'!$B$3:$B$246,'Realized Gains & Losses'!B6,'Transaction Log'!$C$3:$C$246,"BUY") -> 35.0874 | D6: {=IFERROR(SUMPRODUCT(('Transaction Log'!$B$3:$B$246=B6)*('Transaction Log'!$C$3:$C$246="BUY")*'Transaction Log'!$H$3:$H$246)/C6,"")} -> 44.679002 | E6: =SUMIFS('Transaction Log'!$E$3:$E$246,'Transaction Log'!$B$3:$B$246,'Realized Gains & Losses'!B6,'Transaction Log'!$C$3:$C$246,"SELL") -> 15.0795 | F6: {=IFERROR(SUMPRODUCT(('Transaction Log'!$B$3:$B$246=B6)*('Transaction Log'!$C$3:$C$246="SELL")*'Transaction Log'!$H$3:$H$246)/E6,)} -> 43.803176 | G6: =SUMIFS('Transaction Log'!$G$3:$G$246,'Transaction Log'!$B$3:$B$246,B6,'Transaction Log'!$C$3:$C$246,"DIV") -> 0.87 | H6: =(E6*(F6-D6))+G6 -> -12.337004
B7: #VALUE! | C7: =SUMIFS('Transaction Log'!$E$3:$E$246,'Transaction Log'!$B$3:$B$246,'Realized Gains & Losses'!B7,'Transaction Log'!$C$3:$C$246,"BUY") -> 35.0017 | D7: {=IFERROR(SUMPRODUCT(('Transaction Log'!$B$3:$B$246=B7)*('Transaction Log'!$C$3:$C$246="BUY")*'Transaction Log'!$H$3:$H$246)/C7,"")} -> 33.413234 | E7: =SUMIFS('Transaction Log'!$E$3:$E$246,'Transaction Log'!$B$3:$B$246,'Realized Gains & Losses'!B7,'Transaction Log'!$C$3:$C$246,"SELL") -> 26 | F7: {=IFERROR(SUMPRODUCT(('Transaction Log'!$B$3:$B$246=B7)*('Transaction Log'!$C$3:$C$246="SELL")*'Transaction Log'!$H$3:$H$246)/E7,)} -> 30.188462 | G7: =SUMIFS('Transaction Log'!$G$3:$G$246,'Transaction Log'!$B$3:$B$246,B7,'Transaction Log'!$C$3:$C$246,"DIV") -> 0.1 | H7: =(E7*(F7-D7))+G7 -> -83.74409
B8: #VALUE! | C8: =SUMIFS('Transaction Log'!$E$3:$E$246,'Transaction Log'!$B$3:$B$246,'Realized Gains & Losses'!B8,'Transaction Log'!$C$3:$C$246,"BUY") -> 7 | D8: {=IFERROR(SUMPRODUCT(('Transaction Log'!$B$3:$B$246=B8)*('Transaction Log'!$C$3:$C$246="BUY")*'Transaction Log'!$H$3:$H$246)/C8,"")} -> 26.687143 | E8: =SUMIFS('Transaction Log'!$E$3:$E$246,'Transaction Log'!$B$3:$B$246,'Realized Gains & Losses'!B8,'Transaction Log'!$C$3:$C$246,"SELL") -> 7 | F8: {=IFERROR(SUMPRODUCT(('Transaction Log'!$B$3:$B$246=B8)*('Transaction Log'!$C$3:$C$246="SELL")*'Transaction Log'!$H$3:$H$246)/E8,)} -> 27.274286 | G8: =SUMIFS('Transaction Log'!$G$3:$G$246,'Transaction Log'!$B$3:$B$246,B8,'Transaction Log'!$C$3:$C$246,"DIV") -> 1.01 | H8: =(E8*(F8-D8))+G8 -> 5.12
B9: #VALUE! | C9: =SUMIFS('Transaction Log'!$E$3:$E$246,'Transaction Log'!$B$3:$B$246,'Realized Gains & Losses'!B9,'Transaction Log'!$C$3:$C$246,"BUY") -> 65.5594 | D9: {=IFERROR(SUMPRODUCT(('Transaction Log'!$B$3:$B$246=B9)*('Transaction Log'!$C$3:$C$246="BUY")*'Transaction Log'!$H$3:$H$246)/C9,"")} -> 48.545746 | E9: =SUMIFS('Transaction Log'!$E$3:$E$246,'Transaction Log'!$B$3:$B$246,'Realized Gains & Losses'!B9,'Transaction Log'!$C$3:$C$246,"SELL") -> 58.5128 | F9: {=IFERROR(SUMPRODUCT(('Transaction Log'!$B$3:$B$246=B9)*('Transaction Log'!$C$3:$C$246="SELL")*'Transaction Log'!$H$3:$H$246)/E9,)} -> 50.193291 | G9: =SUMIFS('Transaction Log'!$G$3:$G$246,'Transaction Log'!$B$3:$B$246,B9,'Transaction Log'!$C$3:$C$246,"DIV") -> 27.14 | H9: =(E9*(F9-D9))+G9 -> 123.54246
B10: #VALUE! | C10: =SUMIFS('Transaction Log'!$E$3:$E$246,'Transaction Log'!$B$3:$B$246,'Realized Gains & Losses'!B10,'Transaction Log'!$C$3:$C$246,"BUY") -> 28.0336 | D10: {=IFERROR(SUMPRODUCT(('Transaction Log'!$B$3:$B$246=B10)*('Transaction Log'!$C$3:$C$246="BUY")*'Transaction Log'!$H$3:$H$246)/C10,"")} -> 50.041736 | E10: =SUMIFS('Transaction Log'!$E$3:$E$246,'Transaction Log'!$B$3:$B$246,'Realized Gains & Losses'!B10,'Transaction Log'!$C$3:$C$246,"SELL") -> 28.0336 | F10: {=IFERROR(SUMPRODUCT(('Transaction Log'!$B$3:$B$246=B10)*('Transaction Log'!$C$3:$C$246="SELL")*'Transaction Log'!$H$3:$H$246)/E10,)} -> 50.119856 | G10: =SUMIFS('Transaction Log'!$G$3:$G$246,'Transaction Log'!$B$3:$B$246,B10,'Transaction Log'!$C$3:$C$246,"DIV") -> 4.65 | H10: =(E10*(F10-D10))+G10 -> 6.84
B11: #VALUE! | C11: =SUMIFS('Transaction Log'!$E$3:$E$246,'Transaction Log'!$B$3:$B$246,'Realized Gains & Losses'!B11,'Transaction Log'!$C$3:$C$246,"BUY") -> 36.0293 | D11: {=IFERROR(SUMPRODUCT(('Transaction Log'!$B$3:$B$246=B11)*('Transaction Log'!$C$3:$C$246="BUY")*'Transaction Log'!$H$3:$H$246)/C11,"")} -> 31.798009 | E11: =SUMIFS('Transaction Log'!$E$3:$E$246,'Transaction Log'!$B$3:$B$246,'Realized Gains & Losses'!B11,'Transaction Log'!$C$3:$C$246,"SELL") -> 21 | F11: {=IFERROR(SUMPRODUCT(('Transaction Log'!$B$3:$B$246=B11)*('Transaction Log'!$C$3:$C$246="SELL")*'Transaction Log'!$H$3:$H$246)/E11,)} -> 35.417143 | G11: =SUMIFS('Transaction Log'!$G$3:$G$246,'Transaction Log'!$B$3:$B$246,B11,'Transaction Log'!$C$3:$C$246,"DIV") -> 1.48 | H11: =(E11*(F11-D11))+G11 -> 77.481814
B12: #VALUE! | C12: =SUMIFS('Transaction Log'!$E$3:$E$246,'Transaction Log'!$B$3:$B$246,'Realized Gains & Losses'!B12,'Transaction Log'!$C$3:$C$246,"BUY") -> 2 | D12: {=IFERROR(SUMPRODUCT(('Transaction Log'!$B$3:$B$246=B12)*('Transaction Log'!$C$3:$C$246="BUY")*'Transaction Log'!$H$3:$H$246)/C12,"")} -> 117.045 | E12: =SUMIFS('Transaction Log'!$E$3:$E$246,'Transaction Log'!$B$3:$B$246,'Realized Gains & Losses'!B12,'Transaction Log'!$C$3:$C$246,"SELL") -> 2 | F12: {=IFERROR(SUMPRODUCT(('Transaction Log'!$B$3:$B$246=B12)*('Transaction Log'!$C$3:$C$246="SELL")*'Transaction Log'!$H$3:$H$246)/E12,)} -> 117.65 | G12: =SUMIFS('Transaction Log'!$G$3:$G$246,'Transaction Log'!$B$3:$B$246,B12,'Transaction Log'!$C$3:$C$246,"DIV") -> 3.1 | H12: =(E12*(F12-D12))+G12 -> 4.31
B13: #VALUE! | C13: =SUMIFS('Transaction Log'!$E$3:$E$246,'Transaction Log'!$B$3:$B$246,'Realized Gains & Losses'!B13,'Transaction Log'!$C$3:$C$246,"BUY") -> 1 | D13: {=IFERROR(SUMPRODUCT(('Transaction Log'!$B$3:$B$246=B13)*('Transaction Log'!$C$3:$C$246="BUY")*'Transaction Log'!$H$3:$H$246)/C13,"")} -> 29.47 | E13: =SUMIFS('Transaction Log'!$E$3:$E$246,'Transaction Log'!$B$3:$B$246,'Realized Gains & Losses'!B13,'Transaction Log'!$C$3:$C$246,"SELL") -> 1 | F13: {=IFERROR(SUMPRODUCT(('Transaction Log'!$B$3:$B$246=B13)*('Transaction Log'!$C$3:$C$246="SELL")*'Transaction Log'!$H$3:$H$246)/E13,)} -> 26.87 | G13: =SUMIFS('Transaction Log'!$G$3:$G$246,'Transaction Log'!$B$3:$B$246,B13,'Transaction Log'!$C$3:$C$246,"DIV") -> 0 | H13: =(E13*(F13-D13))+G13 -> -2.6
B14: #VALUE! | C14: =SUMIFS('Transaction Log'!$E$3:$E$246,'Transaction Log'!$B$3:$B$246,'Realized Gains & Losses'!B14,'Transaction Log'!$C$3:$C$246,"BUY") -> 18 | D14: {=IFERROR(SUMPRODUCT(('Transaction Log'!$B$3:$B$246=B14)*('Transaction Log'!$C$3:$C$246="BUY")*'Transaction Log'!$H$3:$H$246)/C14,"")} -> 24.319444 | E14: =SUMIFS('Transaction Log'!$E$3:$E$246,'Transaction Log'!$B$3:$B$246,'Realized Gains & Losses'!B14,'Transaction Log'!$C$3:$C$246,"SELL") -> 2 | F14: {=IFERROR(SUMPRODUCT(('Transaction Log'!$B$3:$B$246=B14)*('Transaction Log'!$C$3:$C$246="SELL")*'Transaction Log'!$H$3:$H$246)/E14,)} -> 21.15 | G14: =SUMIFS('Transaction Log'!$G$3:$G$246,'Transaction Log'!$B$3:$B$246,B14,'Transaction Log'!$C$3:$C$246,"DIV") -> 0 | H14: =(E14*(F14-D14))+G14 -> -6.3388889
B15: #VALUE! | C15: =SUMIFS('Transaction Log'!$E$3:$E$246,'Transaction Log'!$B$3:$B$246,'Realized Gains & Losses'!B15,'Transaction Log'!$C$3:$C$246,"BUY") -> 3.0329 | D15: {=IFERROR(SUMPRODUCT(('Transaction Log'!$B$3:$B$246=B15)*('Transaction Log'!$C$3:$C$246="BUY")*'Transaction Log'!$H$3:$H$246)/C15,"")} -> 166.61611 | E15: =SUMIFS('Transaction Log'!$E$3:$E$246,'Transaction Log'!$B$3:$B$246,'Realized Gains & Losses'!B15,'Transaction Log'!$C$3:$C$246,"SELL") -> 1 | F15: {=IFERROR(SUMPRODUCT(('Transaction Log'!$B$3:$B$246=B15)*('Transaction Log'!$C$3:$C$246="SELL")*'Transaction Log'!$H$3:$H$246)/E15,)} -> 167.66 | G15: =SUMIFS('Transaction Log'!$G$3:$G$246,'Transaction Log'!$B$3:$B$246,B15,'Transaction Log'!$C$3:$C$246,"DIV") -> 6.07 | H15: =(E15*(F15-D15))+G15 -> 7.11389
B16: #VALUE! | C16: =SUMIFS('Transaction Log'!$E$3:$E$246,'Transaction Log'!$B$3:$B$246,'Realized Gains & Losses'!B16,'Transaction Log'!$C$3:$C$246,"BUY") -> 15 | D16: {=IFERROR(SUMPRODUCT(('Transaction Log'!$B$3:$B$246=B16)*('Transaction Log'!$C$3:$C$246="BUY")*'Transaction Log'!$H$3:$H$246)/C16,"")} -> 60.12 | E16: =SUMIFS('Transaction Log'!$E$3:$E$246,'Transaction Log'!$B$3:$B$246,'Realized Gains & Losses'!B16,'Transaction Log'!$C$3:$C$246,"SELL") -> 14 | F16: {=IFERROR(SUMPRODUCT(('Transaction Log'!$B$3:$B$246=B16)*('Transaction Log'!$C$3:$C$246="SELL")*'Transaction Log'!$H$3:$H$246)/E16,)} -> 61.194286 | G16: =SUMIFS('Transaction Log'!$G$3:$G$246,'Transaction Log'!$B$3:$B$246,B16,'Transaction Log'!$C$3:$C$246,"DIV") -> 5.49 | H16: =(E16*(F16-D16))+G16 -> 20.53
... B29: #VALUE! | C29: =SUMIFS('Transaction Log'!$E$3:$E$246,'Transaction Log'!$B$3:$B$246,'Realized Gains & Losses'!B29,'Transaction Log'!$C$3:$C$246,"BUY") -> 3 | D29: {=IFERROR(SUMPRODUCT(('Transaction Log'!$B$3:$B$246=B29)*('Transaction Log'!$C$3:$C$246="BUY")*'Transaction Log'!$H$3:$H$246)/C29,"")} -> 61.496667 | E29: =SUMIFS('Transaction Log'!$E$3:$E$246,'Transaction Log'!$B$3:$B$246,'Realized Gains & Losses'!B29,'Transaction Log'!$C$3:$C$246,"SELL") -> 0 | F29: {=IFERROR(SUMPRODUCT(('Transaction Log'!$B$3:$B$246=B29)*('Transaction Log'!$C$3:$C$246="SELL")*'Transaction Log'!$H$3:$H$246)/E29,)} -> 0 | G29: =SUMIFS('Transaction Log'!$G$3:$G$246,'Transaction Log'!$B$3:$B$246,B29,'Transaction Log'!$C$3:$C$246,"DIV") -> 0 | H29: =(E29*(F29-D29))+G29 -> 0
D30: {=IFERROR(SUMPRODUCT(('Transaction Log'!$B$3:$B$246=B30)*('Transaction Log'!$C$3:$C$246="BUY")*'Transaction Log'!$H$3:$H$246)/C30,"")}

Sheet Chart Data Source
B2: Cap Size | C2: Allocation % | E2: Sector | F2: Allocation %
B3: {=_xlfn.UNIQUE(Dashboard!E7:E22)} -> Large | C3: =SUMIF(Dashboard!E7:E22,'Chart Data Source'!B3,Dashboard!I7:I22) -> 0.71351308 | E3: {=_xlfn.UNIQUE(Dashboard!C7:C22)} -> Global Equity ETF | F3: =SUMIF(Dashboard!C7:C22,'Chart Data Source'!E3,Dashboard!I7:I22) -> 0.21955716
B4: Mid | C4: =SUMIF(Dashboard!E8:E24,'Chart Data Source'!B4,Dashboard!I8:I24) -> 0.081129209 | E4: US Equity ETF | F4: =SUMIF(Dashboard!C8:C24,'Chart Data Source'!E4,Dashboard!I8:I24) -> 0.39126366
B5: Small | C5: =SUMIF(Dashboard!E9:E24,'Chart Data Source'!B5,Dashboard!I9:I24) -> 0.058030761 | E5: Technology Equity ETF | F5: =SUMIF(Dashboard!C9:C24,'Chart Data Source'!E5,Dashboard!I9:I24) -> 0.048114759
B6: N/A | C6: =SUMIF(Dashboard!E10:E25,'Chart Data Source'!B6,Dashboard!I10:I25) -> 0.14732695 | E6: Semiconductors & Semiconductor Equipment | F6: =SUMIF(Dashboard!C10:C25,'Chart Data Source'!E6,Dashboard!I10:I25) -> 0.016563827
E7: Canadian Dividend ETF | F7: =SUMIF(Dashboard!C11:C26,'Chart Data Source'!E7,Dashboard!I11:I26) -> 0.019111838
E8: Consumer Technology / Hardware | F8: =SUMIF(Dashboard!C12:C27,'Chart Data Source'!E8,Dashboard!I12:I27) -> 0.026608346
E9: Consumer Discretionary / E-Commerce & Retail | F9: =SUMIF(Dashboard!C13:C28,'Chart Data Source'!E9,Dashboard!I13:I28) -> 0.01894375
E10: Banking Services | F10: =SUMIF(Dashboard!C14:C29,'Chart Data Source'!E10,Dashboard!I14:I29) -> 0.020265398
E11: Oil & Gas Midstream / Pipelines | F11: =SUMIF(Dashboard!C15:C30,'Chart Data Source'!E11,Dashboard!I15:I30) -> 0.0029535287
E12: Utilities & Power Generation | F12: =SUMIF(Dashboard!C16:C31,'Chart Data Source'!E12,Dashboard!I16:I31) -> 0.0055317667
E13: Global Growth / Innovation ETF | F13: =SUMIF(Dashboard!C17:C32,'Chart Data Source'!E13,Dashboard!I17:I32) -> 0.058030761
E14: Nuclear Energy / Energy Technology | F14: =SUMIF(Dashboard!C18:C33,'Chart Data Source'!E14,Dashboard!I18:I33) -> 0.0046418931
E15: Money Market ETF | F15: =SUMIF(Dashboard!C19:C34,'Chart Data Source'!E15,Dashboard!I19:I34) -> 0.14732695
E16: Passenger Transportation / Airlines | F16: =SUMIF(Dashboard!C20:C35,'Chart Data Source'!E16,Dashboard!I20:I35) -> 0.0083708451
E17: Freight & Logistics Services | F17: =SUMIF(Dashboard!C21:C36,'Chart Data Source'!E17,Dashboard!I21:I36) -> 0.0042089337
E18: Canadian Equity ETF | F18: =SUMIF(Dashboard!C22:C37,'Chart Data Source'!E18,Dashboard!I22:I37) -> 0.0085065885
